Workbook

Sheet introduction and title 
B2: INDIAN INSTITUTE OF FOREST MANAGEMENT
B3: FAR ASSIGNMENT
B4: Ratio analysis of Mahindra and Mahindra
B5: ASSINGNMENT SUBMITTED BY
B6: KARTIK AGRAWAL | C6: 26SM22
B7: OMKAR RAMSWARUP MADAVI | C7: 26SM23
B9: SUMBITTED TO
B10: PROF. ASHUTOSH VERMA

Sheet balance sheet 
C2: BALANCE SHEET FOR MAHINDRA AND MAHINDRA FOR FINANCIAL YEAR 2024 AND 2024 (ALL VALUES ARE IN CR)
C4: PERTICULERS | D4: 45717 | E4: 45352
C5: A. EQUITY AND LIABILITIES
C6: 1.EQUITY
C7: Equity share capital | D7: 558.15 | E7: 557.38
C8: Other equity | D8: 76480.71 | E8: 65633.17
C9: Equity attributable to owners of the company | D9: 77038.86 | E9: 66190.55
C10: Non-controlling interests | D10: 12059.14 | E10: 11318.79
C11: TOTAL EQUITY | D11: 89098 | E11: 77509.34
C12: 2. LIABILITIES
C13: a)NON CURRENT LAIBILITIES
C14: Financial liabilities - Borrowings | D14: 79707.19 | E14: 67719.69
C15: Financial liabilities - Compulsorily convertible preference shares | D15: 4075.27 | E15: 2021.73
C16: Financial liabilities - Lease liabilities | D16: 3170.14 | E16: 2813.92
C17: Financial liabilities - Other financial liabilities | D17: 1127.76 | E17: 1208.5
C18: Provisions | D18: 1982.02 | E18: 1763.28
C19: Deferred tax liabilities (net) | D19: 1912.07 | E19: 1772.13
C20: Other non-current liabilities | D20: 6191.81 | E20: 5946.49
C21: TOTAL NON-CURRENT LIABILITIES | D21: 98166.26 | E21: 83245.74
C22: b)CURRENT LIABILITIES
C23: Financial liabilities - Borrowings | D23: 41465.76 | E23: 35483.54
C24: Financial liabilities - Lease liabilities | D24: 606.22 | E24: 608.37
C25: Trade payables - Micro and small enterprises | D25: 926.72 | E25: 459.7
C26: Trade payables - Creditors other than micro and small enterprises | D26: 29928.58 | E26: 25205.94
C27: Financial liabilities - Other financial liabilities | D27: 5542.63 | E27: 4480.96
C28: Other current liabilities | D28: 9818.62 | E28: 7641.62
C29: Provisions | D29: 1313.8 | E29: 1123
C30: Current tax liabilities (net) | D30: 719.68 | E30: 542.52
C31: TOTAL CURRENT LIABILITIES | D31: 90322.01 | E31: 75545.65
C32: TOTAL EQUITY AND LIABILITIES | D32: 277586.27 | E32: 236300.73
C34: A)ASSETS
C35: 1) NON CURRENT ASSETS
C36: Property, plant and equipment | D36: 25834.82 | E36: 21408.6
C37: Capital work-in-progress | D37: 3652.56 | E37: 3461.33
C38: Goodwill | D38: 2373.9 | E38: 2448.37
C39: Other intangible assets | D39: 6427.64 | E39: 4272.44
C40: Intangible assets under development | D40: 4645.08 | E40: 4577.97
C41: Investments accounted using equity method | D41: 14176.68 | E41: 13800.71
C42: Financial assets - Investments | D42: 5184.42 | E42: 7772.75
C43: Financial assets - Trade receivables | D43: 256.54 | E43: 270.66
...

Sheet profit and loss statement 
C2: PROFIT AND LOSS STATEMENT FOR MAHINDRA AND MAHINDRA FOR 2025
C4: PARTICULARS | D4: 45717 | E4: 45352
C5: 1. INCOME
C6: Revenue from operations | D6: 158749.75 | E6: 138279.3
C7: Income from investments related to subsidiaries, associates and joint ventures | D7: 461.07 | E7: 798.97
C8: Income from operations | D8: 159210.82 | E8: 139078.27
C9: Other income | D9: 2181.05 | E9: 2176.42
C10: TOTAL INCOME | D10: 161391.87 | E10: 141254.69
C11: 2. EXPENSES
C12: Cost of materials consumed | D12: 88111.05 | E12: 77848.82
C13: Purchases of stock-in-trade | D13: 7643.85 | E13: 7221.25
C14: Changes in inventories of finished goods, stock-in-trade and work-in-progress | D14: -12.18 | E14: -1455.32
C15: Employee benefits expense | D15: 11126.17 | E15: 10624.33
C16: Finance costs | D16: 9083.39 | E16: 7488.21
C17: Depreciation, amortisation and impairment expense | D17: 6073.65 | E17: 4723.78
C18: Loss from investments related to subsidiaries, associates and joint ventures | D18: 30.84 | E18: 32.92
C19: Other expenses | D19: 21792.9 | E19: 19914.34
C20: TOTAL EXPENSES | D20: 143849.67 | E20: 126398.33
C21: Profit/(loss) before share of profit/(loss) of associates, joint ventures and tax | D21: 17542.2 | E21: 14856.36
C22: Share of profit of associates and joint ventures (net) | D22: 1537.42 | E22: 1121.43
C23: PROFIT/(LOSS) BEFORE TAX | D23: 19079.62 | E23: 15977.79
C24: 3. TAX EXPENSE
C25: Current tax | D25: -4851.93 | E25: -3597.39
C26: Deferred tax | D26: -154.52 | E26: -110.58
C27: PROFIT/(LOSS) AFTER TAX | D27: 14073.17 | E27: 12269.82
C28: 4. OTHER COMPREHENSIVE INCOME/(LOSS)
C29: Items that will not be reclassified to profit or loss | D29: -132.95 | E29: 139.76
C30: Income tax relating to items that will not be reclassified to profit or loss | D30: 21.9 | E30: -43.33
C31: Items that will be reclassified to profit or loss | D31: 310.88 | E31: 83.36
C32: Income tax relating to items that will be reclassified to profit or loss | D32: -19.75 | E32: 4.37
C33: TOTAL COMPREHENSIVE INCOME/(LOSS) | D33: 14253.25 | E33: 12453.98
C34: Profit/(loss) for the period attributable to owners of the company | D34: 12929.1 | E34: 11268.64
C35: Profit/(loss) for the period attributable to non-controlling interest | D35: 1144.07 | E35: 1001.18
C36: Other comprehensive income/(loss) for the period attributable to owners of the company | D36: 150.86 | E36: 142.08
C37: Other comprehensive income/(loss) for the period attributable to non-controlling interest | D37: 29.22 | E37: 42.08
C38: Total comprehensive income/(loss) attributable to owners of the company | D38: 13079.96 | E38: 11410.72
C39: Total comprehensive income/(loss) attributable to non-controlling interest | D39: 1173.29 | E39: 1043.26
C40: Basic earnings per share (Rs.) | D40: 115.91 | E40: 101.14
... C43: Other equity | D43: 76480.71 | E43: 65633.17

Sheet cash flow
C1: CASH FLOW OF MAHINDRA AND MAHINDRA FOR 2025
C3: Particulars | D3: 2025 | E3: 2024
C4: A. CASH FLOW FROM OPERATING ACTIVITIES
C5: Profit/(loss) before share of profit/(loss) of associates, joint ventures and tax | D5: 17542.2 | E5: 14856.36
C6: Adjustments for:
C7: Depreciation, amortisation and impairment expense | D7: 6073.65 | E7: 4723.78
C8: Loss/(Gain) on foreign exchange fluctuation and other adjustments (net) | D8: 44.6 | E8: -74.33
C9: (Gain)/Loss on fair valuation of compulsorily convertible preference shares | D9: -18.18 | E9: 43.45
C10: Income from investments related to subsidiaries, associates and joint ventures | D10: -461.07 | E10: -798.97
C11: Loss from investments related to subsidiaries, associates and joint ventures | D11: 30.84 | E11: 32.92
C12: Dividend on investments and interest income (excluding financial services business) | D12: -1242.5 | E12: -784.77
C13: Finance costs (excluding financial services business) | D13: 681.51 | E13: 544.06
C14: Equity-settled share-based payment expenses | D14: 120.15 | E14: 128.86
C15: Gain on financial instruments measured at fair value (net) | D15: -388.15 | E15: -1069.91
C16: Gain on property, plant and equipment sold / scrapped / written off (net) | D16: -333.21 | E16: -60.21
C17: Total adjustments | D17: 4507.64 | E17: 2684.88
C18: Operating profit before working capital changes | D18: 22049.84 | E18: 17541.24
C19: Changes in:
C20: Trade and other receivables | D20: -3781.89 | E20: -1889.81
C21: Financial services receivable | D21: -17170.29 | E21: -19887
C22: Inventories | D22: -1646.35 | E22: -1752.64
C23: Trade and other payables and provisions | D23: 8485.19 | E23: 4354.36
C24: Total changes in working capital | D24: -14113.34 | E24: -19175.09
C25: Cash generated from/(used in) operations | D25: 7936.5 | E25: -1633.85
C26: Income taxes paid (net) | D26: -4760.69 | E26: -3996.1
C27: NET CASH FLOW FROM/(USED IN) OPERATING ACTIVITIES | D27: 3175.81 | E27: -5629.95
C28: B. CASH FLOW FROM INVESTING ACTIVITIES
C29: Payments to acquire property, plant & equipment and other intangible assets | D29: -10391.95 | E29: -9945.99
C30: Proceeds from sale of property, plant & equipment and other intangible assets | D30: 582.96 | E30: 273.23
C31: Payments to acquire investments | D31: -90594.98 | E31: -49926.64
C32: Proceeds from sale of investments | D32: 85257.15 | E32: 50919.36
C33: Interest received (excluding financial services business) | D33: 883.9 | E33: 703.28
C34: Dividends received from joint ventures and associates | D34: 1364.65 | E34: 1200.31
C35: Dividends received from others | D35: 9.55 | E35: 12.38
C36: Proceeds from capital reduction/buy back of shares by joint venture | D36: 59.71 | E36: 27.27
C37: Bank deposits placed | D37: -15139.63 | E37: -12270.39
C38: Bank deposits matured | D38: 9034.06 | E38: 12199.41
C39: Changes in earmarked and margin account with banks (net) | D39: 20.83 | E39: 10.23
C40: Inter corporate deposits placed | D40: -471 | E40: -410.08
... C46: NET CASH FLOW USED IN INVESTING ACTIVITIES | D46: -18626.11 | E46: -5597.77
...

Sheet ratio analysis
C1: RATIO ANALYSIS
C3: Ratio | D3: Formula | E3: FY2025 | F3: FY2024 | G3: INTERPRETATION
C4: Current Ratio | D4: Current Assets / Current Liabilities | E4: ='balance sheet '!D60/'balance sheet '!D31 -> 1.4013558 | F4: ='balance sheet '!E60/'balance sheet '!E31 -> 1.3007452 | G4: increase in curreent ratio shows that the ability to meet its short term ability tto meet short term obligation has improved .
C5: Quick Ratio | D5: (CA − Inventories) / CL | E5: =('balance sheet '!D60-'balance sheet '!D51)/'balance sheet '!D31 -> 1.1762619 | F5: =('balance sheet '!E60-'balance sheet '!E51)/'balance sheet '!E31 -> 1.0546626 | G5: the increase in quick ratio shows that company is in better position to pay its short term liabilities .
C7: Debt-to-Equity | D7: Total Debt / Shareholders’ Equity | E7: =('balance sheet '!D14+'balance sheet '!D23)/'balance sheet '!D11 -> 1.3599963 | F7: =('balance sheet '!E14+'balance sheet '!E23)/'balance sheet '!E11 -> 1.3314941 | G7: the slight increase in debt to equity ratio shows that company is taking little more debt as compared to shareholder's fund
C8: Interest Coverage | D8: EBIT / Interest Expense | E8: =('profit and loss statement '!D23+'profit and loss statement '!D16)/'profit and loss statement '!D16 -> 3.1004955 | F8: =('profit and loss statement '!E23+'profit and loss statement '!E16)/'profit and loss statement '!E16 -> 3.1337262 | G8: The interest coverage decline shows that Company's ability to cover its interest expense from operating earnings has weakened slightly .
C10: Inventory Turnover | D10: COGS / Avg Inventory | E10: =('profit and loss statement '!D12+'profit and loss statement '!D13+'profit and loss statement '!D14)/'balance sheet '!D51 -> 4.709215 | F10: =('profit and loss statement '!E12+'profit and loss statement '!E13+'profit and loss statement '!E14)/'balance sheet '!E51 -> 4.4977211 | G10: Improvement in inventory turnover suggests that Company's selling and replacing its inventory slightly faster .
C11: Debtors Turnover | D11: Revenue / Trade Receivables | E11: ='profit and loss statement '!D6/'balance sheet '!D53 -> 19.17337 | F11: ='profit and loss statement '!E6/'balance sheet '!E53 -> 18.53759 | G11: The increase in debt turnover indicates that company is collecting money from its customers more efficiently than in previous year .
C12: Total Asset Turnover | D12: Revenue / Total Assets | E12: ='profit and loss statement '!D6/'balance sheet '!D61 -> 0.57189338 | F12: ='profit and loss statement '!E6/'balance sheet '!E61 -> 0.58518355 | G12: Decrease in total asset turnover shows that company generated slightly less revenue for every rupee invested .
C14: Gross Profit Margin | D14: (Revenue − COGS) / Revenue | E14: =('profit and loss statement '!D6-('profit and loss statement '!D12+'profit and loss statement '!D13+'profit and loss statement '!D14))/'profit and loss statement '!D6 -> 0.3968953 | F14: =('profit and loss statement '!E6-('profit and loss statement '!E12+'profit and loss statement '!E13+'profit and loss statement '!E14))/'profit and loss statement '!E6 -> 0.39531983 | G14: Cross profit margin remained unchanged . At 40 % shows Company maintained similar profitability .
C15: Net Profit Margin | D15: PAT / Revenue | E15: ='profit and loss statement '!D27/'profit and loss statement '!D6 -> 0.088650029 | F15: ='profit and loss statement '!E27/'profit and loss statement '!E6 -> 0.088732153 | G15: Net profit margin remained 9% which indicates company was able to maintain its overall profitability and earning around 9 rupees per 100 rupees of revenue .
C16: Return on Assets (ROA) | D16: PAT / Total Assets | E16: ='profit and loss statement '!D27/'balance sheet '!D61 -> 0.050698365 | F16: 0.05 | G16: ROA remained stable at 5 % which means company continued generating roughly the same level of profit from its assets .
C17: Return on Equity (ROE) | D17: PAT / Equity | E17: ='profit and loss statement '!D27/'balance sheet '!D11 -> 0.15795158 | F17: ='profit and loss statement '!D27/'balance sheet '!D11 -> 0.15795158 | G17: ROE remained unchanged at 16 % . This shows Company continued to generate similar return for its shareholder .
